2025-04-21 12:51:48,405 - django.utils.autoreload - INFO - C:\Users\elvac\Documents\AI-powered-people-centric-task-management\backend\ai_integration\urls.py changed, reloading.
2025-04-21 12:52:00,372 - django.utils.autoreload - INFO - C:\Users\elvac\Documents\AI-powered-people-centric-task-management\backend\people\urls.py changed, reloading.
2025-04-21 12:55:27,004 - project.auth_views - ERROR - Registration failed: localhost:27017: [WinError 10061] No connection could be made because the target machine actively refused it (configured timeouts: socketTimeoutMS: 20000.0ms, connectTimeoutMS: 20000.0ms), Timeout: 30s, Topology Description: <TopologyDescription id: 6805cef1bd850612a99abd94, topology_type: Unknown, servers: [<ServerDescription ('localhost', 27017) server_type: Unknown, rtt: None, error=AutoReconnect('localhost:27017: [WinError 10061] No connection could be made because the target machine actively refused it (configured timeouts: socketTimeoutMS: 20000.0ms, connectTimeoutMS: 20000.0ms)')>]>
2025-04-21 12:55:27,009 - project.auth_views - ERROR - Traceback (most recent call last):
  File "C:\Users\elvac\Documents\AI-powered-people-centric-task-management\backend\project\auth_views.py", line 46, in post
    if users_collection.find_one({'username': request.data['username']}):
       ^^^^^^^^^^^^^^^^^^^^^^^^^^^^^^^^^^^^^^^^^^^^^^^^^^^^^^^^^^^^^^^^^
  File "C:\Users\elvac\Documents\AI-powered-people-centric-task-management\backend\venv\Lib\site-packages\pymongo\synchronous\collection.py", line 1755, in find_one
    for result in cursor.limit(-1):
  File "C:\Users\elvac\Documents\AI-powered-people-centric-task-management\backend\venv\Lib\site-packages\pymongo\synchronous\cursor.py", line 1281, in __next__
    return self.next()
           ^^^^^^^^^^^
  File "C:\Users\elvac\Documents\AI-powered-people-centric-task-management\backend\venv\Lib\site-packages\pymongo\synchronous\cursor.py", line 1257, in next
    if len(self._data) or self._refresh():
                          ^^^^^^^^^^^^^^^
  File "C:\Users\elvac\Documents\AI-powered-people-centric-task-management\backend\venv\Lib\site-packages\pymongo\synchronous\cursor.py", line 1205, in _refresh
    self._send_message(q)
  File "C:\Users\elvac\Documents\AI-powered-people-centric-task-management\backend\venv\Lib\site-packages\pymongo\synchronous\cursor.py", line 1100, in _send_message
    response = client._run_operation(
               ^^^^^^^^^^^^^^^^^^^^^^
  File "C:\Users\elvac\Documents\AI-powered-people-centric-task-management\backend\venv\Lib\site-packages\pymongo\_csot.py", line 119, in csot_wrapper
    return func(self, *args, **kwargs)
           ^^^^^^^^^^^^^^^^^^^^^^^^^^^
  File "C:\Users\elvac\Documents\AI-powered-people-centric-task-management\backend\venv\Lib\site-packages\pymongo\synchronous\mongo_client.py", line 1752, in _run_operation
    return self._retryable_read(
           ^^^^^^^^^^^^^^^^^^^^^
  File "C:\Users\elvac\Documents\AI-powered-people-centric-task-management\backend\venv\Lib\site-packages\pymongo\synchronous\mongo_client.py", line 1861, in _retryable_read
    return self._retry_internal(
           ^^^^^^^^^^^^^^^^^^^^^
  File "C:\Users\elvac\Documents\AI-powered-people-centric-task-management\backend\venv\Lib\site-packages\pymongo\_csot.py", line 119, in csot_wrapper
    return func(self, *args, **kwargs)
           ^^^^^^^^^^^^^^^^^^^^^^^^^^^
  File "C:\Users\elvac\Documents\AI-powered-people-centric-task-management\backend\venv\Lib\site-packages\pymongo\synchronous\mongo_client.py", line 1828, in _retry_internal
    ).run()
      ^^^^^
  File "C:\Users\elvac\Documents\AI-powered-people-centric-task-management\backend\venv\Lib\site-packages\pymongo\synchronous\mongo_client.py", line 2565, in run
    return self._read() if self._is_read else self._write()
           ^^^^^^^^^^^^
  File "C:\Users\elvac\Documents\AI-powered-people-centric-task-management\backend\venv\Lib\site-packages\pymongo\synchronous\mongo_client.py", line 2700, in _read
    self._server = self._get_server()
                   ^^^^^^^^^^^^^^^^^^
  File "C:\Users\elvac\Documents\AI-powered-people-centric-task-management\backend\venv\Lib\site-packages\pymongo\synchronous\mongo_client.py", line 2656, in _get_server
    return self._client._select_server(
           ^^^^^^^^^^^^^^^^^^^^^^^^^^^^
  File "C:\Users\elvac\Documents\AI-powered-people-centric-task-management\backend\venv\Lib\site-packages\pymongo\synchronous\mongo_client.py", line 1647, in _select_server
    server = topology.select_server(
             ^^^^^^^^^^^^^^^^^^^^^^^
  File "C:\Users\elvac\Documents\AI-powered-people-centric-task-management\backend\venv\Lib\site-packages\pymongo\synchronous\topology.py", line 401, in select_server
    server = self._select_server(
             ^^^^^^^^^^^^^^^^^^^^
  File "C:\Users\elvac\Documents\AI-powered-people-centric-task-management\backend\venv\Lib\site-packages\pymongo\synchronous\topology.py", line 379, in _select_server
    servers = self.select_servers(
              ^^^^^^^^^^^^^^^^^^^^
  File "C:\Users\elvac\Documents\AI-powered-people-centric-task-management\backend\venv\Lib\site-packages\pymongo\synchronous\topology.py", line 286, in select_servers
    server_descriptions = self._select_servers_loop(
                          ^^^^^^^^^^^^^^^^^^^^^^^^^^
  File "C:\Users\elvac\Documents\AI-powered-people-centric-task-management\backend\venv\Lib\site-packages\pymongo\synchronous\topology.py", line 336, in _select_servers_loop
    raise ServerSelectionTimeoutError(
pymongo.errors.ServerSelectionTimeoutError: localhost:27017: [WinError 10061] No connection could be made because the target machine actively refused it (configured timeouts: socketTimeoutMS: 20000.0ms, connectTimeoutMS: 20000.0ms), Timeout: 30s, Topology Description: <TopologyDescription id: 6805cef1bd850612a99abd94, topology_type: Unknown, servers: [<ServerDescription ('localhost', 27017) server_type: Unknown, rtt: None, error=AutoReconnect('localhost:27017: [WinError 10061] No connection could be made because the target machine actively refused it (configured timeouts: socketTimeoutMS: 20000.0ms, connectTimeoutMS: 20000.0ms)')>]>

2025-04-21 12:55:27,011 - django.request - ERROR - Internal Server Error: /api/auth/register/
2025-04-21 12:56:45,337 - project.auth_views - ERROR - Registration failed: localhost:27017: [WinError 10061] No connection could be made because the target machine actively refused it (configured timeouts: socketTimeoutMS: 20000.0ms, connectTimeoutMS: 20000.0ms), Timeout: 30s, Topology Description: <TopologyDescription id: 6805cef1bd850612a99abd94, topology_type: Unknown, servers: [<ServerDescription ('localhost', 27017) server_type: Unknown, rtt: None, error=AutoReconnect('localhost:27017: [WinError 10061] No connection could be made because the target machine actively refused it (configured timeouts: socketTimeoutMS: 20000.0ms, connectTimeoutMS: 20000.0ms)')>]>
2025-04-21 12:56:45,339 - project.auth_views - ERROR - Traceback (most recent call last):
  File "C:\Users\elvac\Documents\AI-powered-people-centric-task-management\backend\project\auth_views.py", line 46, in post
    if users_collection.find_one({'username': request.data['username']}):
       ^^^^^^^^^^^^^^^^^^^^^^^^^^^^^^^^^^^^^^^^^^^^^^^^^^^^^^^^^^^^^^^^^
  File "C:\Users\elvac\Documents\AI-powered-people-centric-task-management\backend\venv\Lib\site-packages\pymongo\synchronous\collection.py", line 1755, in find_one
    for result in cursor.limit(-1):
  File "C:\Users\elvac\Documents\AI-powered-people-centric-task-management\backend\venv\Lib\site-packages\pymongo\synchronous\cursor.py", line 1281, in __next__
    return self.next()
           ^^^^^^^^^^^
  File "C:\Users\elvac\Documents\AI-powered-people-centric-task-management\backend\venv\Lib\site-packages\pymongo\synchronous\cursor.py", line 1257, in next
    if len(self._data) or self._refresh():
                          ^^^^^^^^^^^^^^^
  File "C:\Users\elvac\Documents\AI-powered-people-centric-task-management\backend\venv\Lib\site-packages\pymongo\synchronous\cursor.py", line 1205, in _refresh
    self._send_message(q)
  File "C:\Users\elvac\Documents\AI-powered-people-centric-task-management\backend\venv\Lib\site-packages\pymongo\synchronous\cursor.py", line 1100, in _send_message
    response = client._run_operation(
               ^^^^^^^^^^^^^^^^^^^^^^
  File "C:\Users\elvac\Documents\AI-powered-people-centric-task-management\backend\venv\Lib\site-packages\pymongo\_csot.py", line 119, in csot_wrapper
    return func(self, *args, **kwargs)
           ^^^^^^^^^^^^^^^^^^^^^^^^^^^
  File "C:\Users\elvac\Documents\AI-powered-people-centric-task-management\backend\venv\Lib\site-packages\pymongo\synchronous\mongo_client.py", line 1752, in _run_operation
    return self._retryable_read(
           ^^^^^^^^^^^^^^^^^^^^^
  File "C:\Users\elvac\Documents\AI-powered-people-centric-task-management\backend\venv\Lib\site-packages\pymongo\synchronous\mongo_client.py", line 1861, in _retryable_read
    return self._retry_internal(
           ^^^^^^^^^^^^^^^^^^^^^
  File "C:\Users\elvac\Documents\AI-powered-people-centric-task-management\backend\venv\Lib\site-packages\pymongo\_csot.py", line 119, in csot_wrapper
    return func(self, *args, **kwargs)
           ^^^^^^^^^^^^^^^^^^^^^^^^^^^
  File "C:\Users\elvac\Documents\AI-powered-people-centric-task-management\backend\venv\Lib\site-packages\pymongo\synchronous\mongo_client.py", line 1828, in _retry_internal
    ).run()
      ^^^^^
  File "C:\Users\elvac\Documents\AI-powered-people-centric-task-management\backend\venv\Lib\site-packages\pymongo\synchronous\mongo_client.py", line 2565, in run
    return self._read() if self._is_read else self._write()
           ^^^^^^^^^^^^
  File "C:\Users\elvac\Documents\AI-powered-people-centric-task-management\backend\venv\Lib\site-packages\pymongo\synchronous\mongo_client.py", line 2700, in _read
    self._server = self._get_server()
                   ^^^^^^^^^^^^^^^^^^
  File "C:\Users\elvac\Documents\AI-powered-people-centric-task-management\backend\venv\Lib\site-packages\pymongo\synchronous\mongo_client.py", line 2656, in _get_server
    return self._client._select_server(
           ^^^^^^^^^^^^^^^^^^^^^^^^^^^^
  File "C:\Users\elvac\Documents\AI-powered-people-centric-task-management\backend\venv\Lib\site-packages\pymongo\synchronous\mongo_client.py", line 1647, in _select_server
    server = topology.select_server(
             ^^^^^^^^^^^^^^^^^^^^^^^
  File "C:\Users\elvac\Documents\AI-powered-people-centric-task-management\backend\venv\Lib\site-packages\pymongo\synchronous\topology.py", line 401, in select_server
    server = self._select_server(
             ^^^^^^^^^^^^^^^^^^^^
  File "C:\Users\elvac\Documents\AI-powered-people-centric-task-management\backend\venv\Lib\site-packages\pymongo\synchronous\topology.py", line 379, in _select_server
    servers = self.select_servers(
              ^^^^^^^^^^^^^^^^^^^^
  File "C:\Users\elvac\Documents\AI-powered-people-centric-task-management\backend\venv\Lib\site-packages\pymongo\synchronous\topology.py", line 286, in select_servers
    server_descriptions = self._select_servers_loop(
                          ^^^^^^^^^^^^^^^^^^^^^^^^^^
  File "C:\Users\elvac\Documents\AI-powered-people-centric-task-management\backend\venv\Lib\site-packages\pymongo\synchronous\topology.py", line 336, in _select_servers_loop
    raise ServerSelectionTimeoutError(
pymongo.errors.ServerSelectionTimeoutError: localhost:27017: [WinError 10061] No connection could be made because the target machine actively refused it (configured timeouts: socketTimeoutMS: 20000.0ms, connectTimeoutMS: 20000.0ms), Timeout: 30s, Topology Description: <TopologyDescription id: 6805cef1bd850612a99abd94, topology_type: Unknown, servers: [<ServerDescription ('localhost', 27017) server_type: Unknown, rtt: None, error=AutoReconnect('localhost:27017: [WinError 10061] No connection could be made because the target machine actively refused it (configured timeouts: socketTimeoutMS: 20000.0ms, connectTimeoutMS: 20000.0ms)')>]>

2025-04-21 12:56:45,340 - django.request - ERROR - Internal Server Error: /api/auth/register/
2025-04-21 13:04:19,969 - django.utils.autoreload - INFO - C:\Users\elvac\Documents\AI-powered-people-centric-task-management\backend\project\settings.py changed, reloading.
2025-04-21 13:10:52,250 - django.request - WARNING - Not Found: /api/tasks/user/6805d35bc44f886f5b3eb189/
2025-04-21 13:10:53,473 - django.request - WARNING - Not Found: /api/tasks/user/6805d35bc44f886f5b3eb189/
2025-04-21 13:11:27,131 - django.request - WARNING - Not Found: /api/tasks/user/6805d35dd45a226e7e5e8070/
2025-04-21 13:11:27,147 - django.request - WARNING - Not Found: /api/tasks/user/6805d35dd45a226e7e5e8070/
2025-04-21 13:11:28,254 - django.request - WARNING - Not Found: /api/tasks/user/6805d35dd45a226e7e5e8070/
2025-04-21 13:12:42,921 - django.request - WARNING - Not Found: /api/tasks/user/6805d35dd45a226e7e5e8070/
2025-04-21 13:12:42,927 - django.request - WARNING - Not Found: /api/tasks/user/6805d35dd45a226e7e5e8070/
2025-04-21 13:13:58,994 - django.utils.autoreload - INFO - C:\Users\elvac\Documents\AI-powered-people-centric-task-management\backend\project\settings.py changed, reloading.
2025-04-21 13:26:24,391 - django.utils.autoreload - INFO - C:\Users\elvac\Documents\AI-powered-people-centric-task-management\backend\project\auth_views.py changed, reloading.
2025-04-21 13:27:45,354 - django.utils.autoreload - INFO - C:\Users\elvac\Documents\AI-powered-people-centric-task-management\backend\people\views.py changed, reloading.
2025-04-22 00:55:44,420 - django.utils.autoreload - INFO - C:\Users\elvac\Documents\AI-powered-people-centric-task-management\backend\project\auth_views.py changed, reloading.
2025-04-22 01:09:14,638 - django.request - WARNING - Unauthorized: /api/auth/user/
2025-04-22 01:09:14,639 - django.server - WARNING - "GET /api/auth/user/ HTTP/1.1" 401 172
2025-04-22 01:09:14,863 - django.request - WARNING - Unauthorized: /api/auth/user/
2025-04-22 01:09:14,864 - django.server - WARNING - "GET /api/auth/user/ HTTP/1.1" 401 172
2025-04-22 01:09:28,371 - django.request - WARNING - Method Not Allowed: /api/auth/register/
2025-04-22 01:09:28,371 - django.server - WARNING - "POST /api/auth/register/ HTTP/1.1" 405 41
2025-04-22 01:16:02,403 - django.utils.autoreload - INFO - C:\Users\elvac\Documents\AI-powered-people-centric-task-management\backend\project\auth_views.py changed, reloading.
2025-04-22 01:16:18,780 - django.request - ERROR - Internal Server Error: /api/auth/register/
2025-04-22 01:16:18,781 - django.server - ERROR - "POST /api/auth/register/ HTTP/1.1" 500 79
2025-04-22 01:19:52,248 - django.utils.autoreload - INFO - C:\Users\elvac\Documents\AI-powered-people-centric-task-management\backend\project\auth_views.py changed, reloading.
2025-04-22 01:20:32,188 - django.request - WARNING - Bad Request: /api/auth/register/
2025-04-22 01:20:32,189 - django.server - WARNING - "POST /api/auth/register/ HTTP/1.1" 400 54
2025-04-22 01:20:59,450 - django.request - WARNING - Bad Request: /api/auth/register/
2025-04-22 01:20:59,451 - django.server - WARNING - "POST /api/auth/register/ HTTP/1.1" 400 54
2025-04-22 01:24:55,214 - django.utils.autoreload - INFO - C:\Users\elvac\Documents\AI-powered-people-centric-task-management\backend\project\auth_views.py changed, reloading.
2025-04-22 01:25:08,902 - django.server - INFO - "POST /api/auth/register/ HTTP/1.1" 201 384
2025-04-22 01:25:08,930 - django.server - INFO - "OPTIONS /api/tasks/user/68067f739cb5483b8cf0379e/ HTTP/1.1" 200 0
2025-04-22 01:25:08,931 - django.server - INFO - "OPTIONS /api/tasks/user/68067f739cb5483b8cf0379e/ HTTP/1.1" 200 0
2025-04-22 01:25:09,166 - django.request - WARNING - Not Found: /api/tasks/user/68067f739cb5483b8cf0379e/
2025-04-22 01:25:09,167 - django.server - WARNING - "GET /api/tasks/user/68067f739cb5483b8cf0379e/ HTTP/1.1" 404 19237
2025-04-22 01:25:10,175 - django.request - WARNING - Not Found: /api/tasks/user/68067f739cb5483b8cf0379e/
2025-04-22 01:25:10,176 - django.server - WARNING - "GET /api/tasks/user/68067f739cb5483b8cf0379e/ HTTP/1.1" 404 19237
2025-04-22 01:25:12,283 - django.server - INFO - "OPTIONS /api/api/auth/user/ HTTP/1.1" 200 0
2025-04-22 01:25:12,283 - django.server - INFO - "OPTIONS /api/api/auth/user/ HTTP/1.1" 200 0
2025-04-22 01:25:12,517 - django.request - WARNING - Not Found: /api/api/auth/user/
2025-04-22 01:25:12,518 - django.server - WARNING - "GET /api/api/auth/user/ HTTP/1.1" 404 19171
2025-04-22 01:25:12,534 - django.request - WARNING - Not Found: /api/api/auth/user/
2025-04-22 01:25:12,535 - django.server - WARNING - "GET /api/api/auth/user/ HTTP/1.1" 404 19171
2025-04-22 01:25:24,260 - django.request - WARNING - Not Found: /api/api/auth/user/
2025-04-22 01:25:24,267 - django.request - WARNING - Not Found: /api/api/auth/user/
2025-04-22 01:25:24,267 - django.server - WARNING - "GET /api/api/auth/user/ HTTP/1.1" 404 19171
2025-04-22 01:25:24,268 - django.server - WARNING - "GET /api/api/auth/user/ HTTP/1.1" 404 19171
2025-04-22 01:25:28,105 - django.request - WARNING - Not Found: /api/api/auth/user/
2025-04-22 01:25:28,112 - django.request - WARNING - Not Found: /api/api/auth/user/
2025-04-22 01:25:28,112 - django.server - WARNING - "GET /api/api/auth/user/ HTTP/1.1" 404 19171
2025-04-22 01:25:28,112 - django.server - WARNING - "GET /api/api/auth/user/ HTTP/1.1" 404 19171
2025-04-22 01:25:35,204 - django.server - INFO - "GET /api/auth/user/ HTTP/1.1" 200 168
2025-04-22 01:25:35,215 - django.server - INFO - "GET /api/auth/user/ HTTP/1.1" 200 168
2025-04-22 01:25:35,461 - django.request - WARNING - Not Found: /api/api/auth/user/
2025-04-22 01:25:35,467 - django.request - WARNING - Not Found: /api/api/auth/user/
2025-04-22 01:25:35,467 - django.server - WARNING - "GET /api/api/auth/user/ HTTP/1.1" 404 19171
2025-04-22 01:25:35,468 - django.server - WARNING - "GET /api/api/auth/user/ HTTP/1.1" 404 19171
2025-04-22 01:25:36,554 - django.request - WARNING - Not Found: /api/api/auth/user/
2025-04-22 01:25:36,555 - django.server - WARNING - "GET /api/api/auth/user/ HTTP/1.1" 404 19171
2025-04-22 01:25:55,499 - django.request - WARNING - Bad Request: /api/auth/register/
2025-04-22 01:25:55,499 - django.server - WARNING - "POST /api/auth/register/ HTTP/1.1" 400 32
2025-04-22 01:28:54,664 - django.utils.autoreload - INFO - C:\Users\elvac\Documents\AI-powered-people-centric-task-management\backend\project\auth_views.py changed, reloading.
2025-04-22 01:29:20,439 - django.server - INFO - "POST /api/auth/register/ HTTP/1.1" 201 384
2025-04-22 01:29:20,487 - django.server - INFO - "OPTIONS /api/tasks/user/6806806f88f474ef59a7a368/ HTTP/1.1" 200 0
2025-04-22 01:29:20,488 - django.server - INFO - "OPTIONS /api/tasks/user/6806806f88f474ef59a7a368/ HTTP/1.1" 200 0
2025-04-22 01:29:20,703 - django.request - WARNING - Not Found: /api/tasks/user/6806806f88f474ef59a7a368/
2025-04-22 01:29:20,704 - django.server - WARNING - "GET /api/tasks/user/6806806f88f474ef59a7a368/ HTTP/1.1" 404 19237
2025-04-22 01:29:21,809 - django.request - WARNING - Not Found: /api/tasks/user/6806806f88f474ef59a7a368/
2025-04-22 01:29:21,809 - django.server - WARNING - "GET /api/tasks/user/6806806f88f474ef59a7a368/ HTTP/1.1" 404 19237
2025-04-22 01:29:25,007 - django.request - WARNING - Not Found: /api/api/auth/user/
2025-04-22 01:29:25,015 - django.request - WARNING - Not Found: /api/api/auth/user/
2025-04-22 01:29:25,016 - django.server - WARNING - "GET /api/api/auth/user/ HTTP/1.1" 404 19171
2025-04-22 01:29:25,016 - django.server - WARNING - "GET /api/api/auth/user/ HTTP/1.1" 404 19171
2025-04-22 01:35:20,137 - django.utils.autoreload - INFO - C:\Users\elvac\Documents\AI-powered-people-centric-task-management\backend\people\views.py changed, reloading.
2025-04-22 01:42:44,520 - django.utils.autoreload - INFO - C:\Users\elvac\Documents\AI-powered-people-centric-task-management\backend\people\views.py changed, reloading.
2025-04-22 01:44:16,614 - django.server - INFO - "OPTIONS /api/api/people/ HTTP/1.1" 200 0
2025-04-22 01:44:16,828 - django.request - WARNING - Not Found: /api/api/people/
2025-04-22 01:44:16,828 - django.server - WARNING - "GET /api/api/people/ HTTP/1.1" 404 19426
2025-04-22 01:44:17,054 - django.request - WARNING - Not Found: /api/api/auth/user/
2025-04-22 01:44:17,055 - django.server - WARNING - "GET /api/api/auth/user/ HTTP/1.1" 404 19435
2025-04-22 01:44:28,258 - django.server - INFO - "GET /api/auth/user/ HTTP/1.1" 200 168
2025-04-22 01:44:28,853 - django.server - INFO - "GET /api/auth/user/ HTTP/1.1" 200 168
2025-04-22 01:44:30,017 - django.request - WARNING - Not Found: /api/api/people/
2025-04-22 01:44:30,018 - django.server - WARNING - "GET /api/api/people/ HTTP/1.1" 404 19426
2025-04-22 01:44:30,038 - django.request - WARNING - Not Found: /api/api/people/
2025-04-22 01:44:30,039 - django.server - WARNING - "GET /api/api/people/ HTTP/1.1" 404 19426
2025-04-22 01:44:30,237 - django.request - WARNING - Not Found: /api/api/auth/user/
2025-04-22 01:44:30,244 - django.request - WARNING - Not Found: /api/api/auth/user/
2025-04-22 01:44:30,244 - django.server - WARNING - "GET /api/api/auth/user/ HTTP/1.1" 404 19435
2025-04-22 01:44:30,245 - django.server - WARNING - "GET /api/api/auth/user/ HTTP/1.1" 404 19435
2025-04-22 01:44:30,729 - django.request - WARNING - Not Found: /api/tasks/user/6806806f88f474ef59a7a368/
2025-04-22 01:44:30,735 - django.request - WARNING - Not Found: /api/tasks/user/6806806f88f474ef59a7a368/
2025-04-22 01:44:30,736 - django.server - WARNING - "GET /api/tasks/user/6806806f88f474ef59a7a368/ HTTP/1.1" 404 19501
2025-04-22 01:44:30,736 - django.server - WARNING - "GET /api/tasks/user/6806806f88f474ef59a7a368/ HTTP/1.1" 404 19501
2025-04-22 01:44:56,513 - django.server - INFO - "POST /api/auth/register/ HTTP/1.1" 201 392
2025-04-22 01:44:56,563 - django.server - INFO - "OPTIONS /api/tasks/user/680684174195dcc6e3ae5b7a/ HTTP/1.1" 200 0
2025-04-22 01:44:56,563 - django.server - INFO - "OPTIONS /api/tasks/user/680684174195dcc6e3ae5b7a/ HTTP/1.1" 200 0
2025-04-22 01:44:56,769 - django.request - WARNING - Not Found: /api/tasks/user/680684174195dcc6e3ae5b7a/
2025-04-22 01:44:56,769 - django.server - WARNING - "GET /api/tasks/user/680684174195dcc6e3ae5b7a/ HTTP/1.1" 404 19501
2025-04-22 01:44:56,779 - django.request - WARNING - Not Found: /api/tasks/user/680684174195dcc6e3ae5b7a/
2025-04-22 01:44:56,780 - django.server - WARNING - "GET /api/tasks/user/680684174195dcc6e3ae5b7a/ HTTP/1.1" 404 19501
2025-04-22 01:45:00,019 - django.request - WARNING - Not Found: /api/api/people/
2025-04-22 01:45:00,020 - django.server - WARNING - "GET /api/api/people/ HTTP/1.1" 404 19426
2025-04-22 01:45:00,034 - django.request - WARNING - Not Found: /api/api/people/
2025-04-22 01:45:00,035 - django.server - WARNING - "GET /api/api/people/ HTTP/1.1" 404 19426
2025-04-22 01:45:00,274 - django.request - WARNING - Not Found: /api/api/auth/user/
2025-04-22 01:45:00,280 - django.request - WARNING - Not Found: /api/api/auth/user/
2025-04-22 01:45:00,282 - django.server - WARNING - "GET /api/api/auth/user/ HTTP/1.1" 404 19435
2025-04-22 01:45:00,282 - django.server - WARNING - "GET /api/api/auth/user/ HTTP/1.1" 404 19435
2025-04-22 02:11:26,892 - django.request - WARNING - Not Found: /api/api/people/
2025-04-22 02:11:26,895 - django.server - WARNING - "GET /api/api/people/ HTTP/1.1" 404 19426
2025-04-22 02:14:54,983 - django.server - INFO - "OPTIONS /api/tasks/ HTTP/1.1" 200 0
2025-04-22 02:14:55,364 - django.request - ERROR - Internal Server Error: /api/tasks/
Traceback (most recent call last):
  File "C:\Users\elvac\Documents\AI-powered-people-centric-task-management\backend\venv\Lib\site-packages\django\core\handlers\exception.py", line 55, in inner
    response = get_response(request)
               ^^^^^^^^^^^^^^^^^^^^^
  File "C:\Users\elvac\Documents\AI-powered-people-centric-task-management\backend\venv\Lib\site-packages\django\core\handlers\base.py", line 197, in _get_response
    response = wrapped_callback(request, *callback_args, **callback_kwargs)
               ^^^^^^^^^^^^^^^^^^^^^^^^^^^^^^^^^^^^^^^^^^^^^^^^^^^^^^^^^^^^
  File "C:\Users\elvac\Documents\AI-powered-people-centric-task-management\backend\venv\Lib\site-packages\django\views\decorators\csrf.py", line 65, in _view_wrapper
    return view_func(request, *args, **kwargs)
           ^^^^^^^^^^^^^^^^^^^^^^^^^^^^^^^^^^^
  File "C:\Users\elvac\Documents\AI-powered-people-centric-task-management\backend\venv\Lib\site-packages\rest_framework\viewsets.py", line 125, in view
    return self.dispatch(request, *args, **kwargs)
           ^^^^^^^^^^^^^^^^^^^^^^^^^^^^^^^^^^^^^^^
  File "C:\Users\elvac\Documents\AI-powered-people-centric-task-management\backend\venv\Lib\site-packages\rest_framework\views.py", line 515, in dispatch
    response = self.handle_exception(exc)
               ^^^^^^^^^^^^^^^^^^^^^^^^^^
  File "C:\Users\elvac\Documents\AI-powered-people-centric-task-management\backend\venv\Lib\site-packages\rest_framework\views.py", line 475, in handle_exception
    self.raise_uncaught_exception(exc)
  File "C:\Users\elvac\Documents\AI-powered-people-centric-task-management\backend\venv\Lib\site-packages\rest_framework\views.py", line 486, in raise_uncaught_exception
    raise exc
  File "C:\Users\elvac\Documents\AI-powered-people-centric-task-management\backend\venv\Lib\site-packages\rest_framework\views.py", line 512, in dispatch
    response = handler(request, *args, **kwargs)
               ^^^^^^^^^^^^^^^^^^^^^^^^^^^^^^^^^
  File "C:\Users\elvac\Documents\AI-powered-people-centric-task-management\backend\tasks\views.py", line 240, in create
    if serializer.is_valid():
       ^^^^^^^^^^^^^^^^^^^^^
  File "C:\Users\elvac\Documents\AI-powered-people-centric-task-management\backend\venv\Lib\site-packages\rest_framework\serializers.py", line 225, in is_valid
    self._validated_data = self.run_validation(self.initial_data)
                           ^^^^^^^^^^^^^^^^^^^^^^^^^^^^^^^^^^^^^^
  File "C:\Users\elvac\Documents\AI-powered-people-centric-task-management\backend\venv\Lib\site-packages\rest_framework\serializers.py", line 444, in run_validation
    value = self.to_internal_value(data)
            ^^^^^^^^^^^^^^^^^^^^^^^^^^^^
  File "C:\Users\elvac\Documents\AI-powered-people-centric-task-management\backend\venv\Lib\site-packages\rest_framework\serializers.py", line 497, in to_internal_value
    for field in fields:
  File "C:\Users\elvac\Documents\AI-powered-people-centric-task-management\backend\venv\Lib\site-packages\rest_framework\serializers.py", line 380, in _writable_fields
    for field in self.fields.values():
                 ^^^^^^^^^^^
  File "C:\Users\elvac\Documents\AI-powered-people-centric-task-management\backend\venv\Lib\site-packages\django\utils\functional.py", line 47, in __get__
    res = instance.__dict__[self.name] = self.func(instance)
                                         ^^^^^^^^^^^^^^^^^^^
  File "C:\Users\elvac\Documents\AI-powered-people-centric-task-management\backend\venv\Lib\site-packages\rest_framework\serializers.py", line 374, in fields
    for key, value in self.get_fields().items():
                      ^^^^^^^^^^^^^^^^^
  File "C:\Users\elvac\Documents\AI-powered-people-centric-task-management\backend\venv\Lib\site-packages\rest_framework\serializers.py", line 1080, in get_fields
    info = model_meta.get_field_info(model)
           ^^^^^^^^^^^^^^^^^^^^^^^^^^^^^^^^
  File "C:\Users\elvac\Documents\AI-powered-people-centric-task-management\backend\venv\Lib\site-packages\rest_framework\utils\model_meta.py", line 35, in get_field_info
    opts = model._meta.concrete_model._meta
           ^^^^^^^^^^^
AttributeError: type object 'Task' has no attribute '_meta'
2025-04-22 02:14:55,373 - django.server - ERROR - "POST /api/tasks/ HTTP/1.1" 500 149540
2025-04-22 02:19:54,795 - django.utils.autoreload - INFO - C:\Users\elvac\Documents\AI-powered-people-centric-task-management\backend\tasks\serializers.py changed, reloading.
2025-04-22 02:21:27,505 - django.request - WARNING - Bad Request: /api/tasks/
2025-04-22 02:21:27,505 - django.server - WARNING - "POST /api/tasks/ HTTP/1.1" 400 41
2025-04-22 02:24:09,735 - django.request - WARNING - Not Found: /api/api/people/
2025-04-22 02:24:09,736 - django.server - WARNING - "GET /api/api/people/ HTTP/1.1" 404 19426
2025-04-22 02:25:13,504 - django.utils.autoreload - INFO - C:\Users\elvac\Documents\AI-powered-people-centric-task-management\backend\tasks\views.py changed, reloading.
2025-04-22 02:25:28,284 - django.request - WARNING - Bad Request: /api/tasks/
2025-04-22 02:25:28,284 - django.server - WARNING - "POST /api/tasks/ HTTP/1.1" 400 41
2025-04-22 02:28:13,092 - django.utils.autoreload - INFO - C:\Users\elvac\Documents\AI-powered-people-centric-task-management\backend\tasks\serializers.py changed, reloading.
2025-04-22 02:28:47,400 - django.request - WARNING - Bad Request: /api/tasks/
2025-04-22 02:28:47,401 - django.server - WARNING - "POST /api/tasks/ HTTP/1.1" 400 41
2025-04-22 04:07:29,130 - django.request - ERROR - Service Unavailable: /api/tasks/user/680684174195dcc6e3ae5b7a/
2025-04-22 04:07:29,130 - django.request - ERROR - Service Unavailable: /api/tasks/user/680684174195dcc6e3ae5b7a/
2025-04-22 04:07:29,131 - django.server - ERROR - "GET /api/tasks/user/680684174195dcc6e3ae5b7a/ HTTP/1.1" 503 44
2025-04-22 04:07:29,131 - django.server - ERROR - "GET /api/tasks/user/680684174195dcc6e3ae5b7a/ HTTP/1.1" 503 44
2025-04-22 04:07:31,257 - django.request - ERROR - Service Unavailable: /api/api/people/
2025-04-22 04:07:31,258 - django.request - ERROR - Service Unavailable: /api/api/people/
2025-04-22 04:07:31,259 - django.server - ERROR - "GET /api/api/people/ HTTP/1.1" 503 44
2025-04-22 04:07:31,259 - django.server - ERROR - "GET /api/api/people/ HTTP/1.1" 503 44
2025-04-22 04:10:34,617 - django.request - ERROR - Service Unavailable: /api/auth/user/
2025-04-22 04:10:34,617 - django.server - ERROR - "GET /api/auth/user/ HTTP/1.1" 503 44
2025-04-22 04:10:39,737 - django.request - ERROR - Service Unavailable: /api/auth/user/
2025-04-22 04:10:39,738 - django.server - ERROR - "GET /api/auth/user/ HTTP/1.1" 503 44
