ERROR 2025-04-22 01:16:18,771 auth_views Registration failed: UNIQUE constraint failed: people_user.username
ERROR 2025-04-22 01:16:18,779 auth_views Traceback (most recent call last):
  File "C:\Users\elvac\Documents\AI-powered-people-centric-task-management\backend\venv\Lib\site-packages\django\db\backends\utils.py", line 105, in _execute
    return self.cursor.execute(sql, params)
           ^^^^^^^^^^^^^^^^^^^^^^^^^^^^^^^^
  File "C:\Users\elvac\Documents\AI-powered-people-centric-task-management\backend\venv\Lib\site-packages\django\db\backends\sqlite3\base.py", line 360, in execute
    return super().execute(query, params)
           ^^^^^^^^^^^^^^^^^^^^^^^^^^^^^^
sqlite3.IntegrityError: UNIQUE constraint failed: people_user.username

The above exception was the direct cause of the following exception:

Traceback (most recent call last):
  File "C:\Users\elvac\Documents\AI-powered-people-centric-task-management\backend\project\auth_views.py", line 107, in post
    django_user = User.objects.create_user(
                  ^^^^^^^^^^^^^^^^^^^^^^^^^
  File "C:\Users\elvac\Documents\AI-powered-people-centric-task-management\backend\venv\Lib\site-packages\django\contrib\auth\models.py", line 175, in create_user
    return self._create_user(username, email, password, **extra_fields)
           ^^^^^^^^^^^^^^^^^^^^^^^^^^^^^^^^^^^^^^^^^^^^^^^^^^^^^^^^^^^^
  File "C:\Users\elvac\Documents\AI-powered-people-centric-task-management\backend\venv\Lib\site-packages\django\contrib\auth\models.py", line 163, in _create_user
    user.save(using=self._db)
  File "C:\Users\elvac\Documents\AI-powered-people-centric-task-management\backend\people\models.py", line 54, in save
    super().save(*args, **kwargs)
  File "C:\Users\elvac\Documents\AI-powered-people-centric-task-management\backend\venv\Lib\site-packages\django\contrib\auth\base_user.py", line 65, in save
    super().save(*args, **kwargs)
  File "C:\Users\elvac\Documents\AI-powered-people-centric-task-management\backend\venv\Lib\site-packages\django\db\models\base.py", line 902, in save
    self.save_base(
  File "C:\Users\elvac\Documents\AI-powered-people-centric-task-management\backend\venv\Lib\site-packages\django\db\models\base.py", line 1008, in save_base
    updated = self._save_table(
              ^^^^^^^^^^^^^^^^^
  File "C:\Users\elvac\Documents\AI-powered-people-centric-task-management\backend\venv\Lib\site-packages\django\db\models\base.py", line 1169, in _save_table
    results = self._do_insert(
              ^^^^^^^^^^^^^^^^
  File "C:\Users\elvac\Documents\AI-powered-people-centric-task-management\backend\venv\Lib\site-packages\django\db\models\base.py", line 1210, in _do_insert
    return manager._insert(
           ^^^^^^^^^^^^^^^^
  File "C:\Users\elvac\Documents\AI-powered-people-centric-task-management\backend\venv\Lib\site-packages\django\db\models\manager.py", line 87, in manager_method
    return getattr(self.get_queryset(), name)(*args, **kwargs)
           ^^^^^^^^^^^^^^^^^^^^^^^^^^^^^^^^^^^^^^^^^^^^^^^^^^^
  File "C:\Users\elvac\Documents\AI-powered-people-centric-task-management\backend\venv\Lib\site-packages\django\db\models\query.py", line 1854, in _insert
    return query.get_compiler(using=using).execute_sql(returning_fields)
           ^^^^^^^^^^^^^^^^^^^^^^^^^^^^^^^^^^^^^^^^^^^^^^^^^^^^^^^^^^^^^
  File "C:\Users\elvac\Documents\AI-powered-people-centric-task-management\backend\venv\Lib\site-packages\django\db\models\sql\compiler.py", line 1881, in execute_sql
    cursor.execute(sql, params)
  File "C:\Users\elvac\Documents\AI-powered-people-centric-task-management\backend\venv\Lib\site-packages\django\db\backends\utils.py", line 122, in execute
    return super().execute(sql, params)
           ^^^^^^^^^^^^^^^^^^^^^^^^^^^^
  File "C:\Users\elvac\Documents\AI-powered-people-centric-task-management\backend\venv\Lib\site-packages\django\db\backends\utils.py", line 79, in execute
    return self._execute_with_wrappers(
           ^^^^^^^^^^^^^^^^^^^^^^^^^^^^
  File "C:\Users\elvac\Documents\AI-powered-people-centric-task-management\backend\venv\Lib\site-packages\django\db\backends\utils.py", line 92, in _execute_with_wrappers
    return executor(sql, params, many, context)
           ^^^^^^^^^^^^^^^^^^^^^^^^^^^^^^^^^^^^
  File "C:\Users\elvac\Documents\AI-powered-people-centric-task-management\backend\venv\Lib\site-packages\django\db\backends\utils.py", line 100, in _execute
    with self.db.wrap_database_errors:
  File "C:\Users\elvac\Documents\AI-powered-people-centric-task-management\backend\venv\Lib\site-packages\django\db\utils.py", line 91, in __exit__
    raise dj_exc_value.with_traceback(traceback) from exc_value
  File "C:\Users\elvac\Documents\AI-powered-people-centric-task-management\backend\venv\Lib\site-packages\django\db\backends\utils.py", line 105, in _execute
    return self.cursor.execute(sql, params)
           ^^^^^^^^^^^^^^^^^^^^^^^^^^^^^^^^
  File "C:\Users\elvac\Documents\AI-powered-people-centric-task-management\backend\venv\Lib\site-packages\django\db\backends\sqlite3\base.py", line 360, in execute
    return super().execute(query, params)
           ^^^^^^^^^^^^^^^^^^^^^^^^^^^^^^
django.db.utils.IntegrityError: UNIQUE constraint failed: people_user.username

ERROR 2025-04-22 04:07:29,127 middleware MongoDB connection lost
ERROR 2025-04-22 04:07:29,127 middleware MongoDB connection lost
ERROR 2025-04-22 04:07:31,256 middleware MongoDB connection lost
ERROR 2025-04-22 04:07:31,256 middleware MongoDB connection lost
ERROR 2025-04-22 04:10:34,617 middleware MongoDB connection lost
ERROR 2025-04-22 04:10:39,737 middleware MongoDB connection lost
